[2025-07-01T04:34:38.467+0000] {taskinstance.py:1956} INFO - Dependencies all met for dep_context=non-requeueable deps ti=<TaskInstance: DAG_atualizacao_cadastral_revendas.insert_database scheduled__2025-06-30T04:30:00+00:00 [queued]>
[2025-07-01T04:34:38.483+0000] {taskinstance.py:1956} INFO - Dependencies all met for dep_context=requeueable deps ti=<TaskInstance: DAG_atualizacao_cadastral_revendas.insert_database scheduled__2025-06-30T04:30:00+00:00 [queued]>
[2025-07-01T04:34:38.484+0000] {taskinstance.py:2170} INFO - Starting attempt 1 of 1
[2025-07-01T04:34:38.538+0000] {taskinstance.py:2191} INFO - Executing <Task(PythonOperator): insert_database> on 2025-06-30 04:30:00+00:00
[2025-07-01T04:34:38.548+0000] {standard_task_runner.py:60} INFO - Started process 538675 to run task
[2025-07-01T04:34:38.556+0000] {standard_task_runner.py:87} INFO - Running: ['***', 'tasks', 'run', 'DAG_atualizacao_cadastral_revendas', 'insert_database', 'scheduled__2025-06-30T04:30:00+00:00', '--job-id', '320', '--raw', '--subdir', 'DAGS_FOLDER/DagDatasetComercial.py', '--cfg-path', '/tmp/tmpfwlf0wya']
[2025-07-01T04:34:38.559+0000] {standard_task_runner.py:88} INFO - Job 320: Subtask insert_database
[2025-07-01T04:34:38.694+0000] {task_command.py:423} INFO - Running <TaskInstance: DAG_atualizacao_cadastral_revendas.insert_database scheduled__2025-06-30T04:30:00+00:00 [running]> on host 99f5714845f7
[2025-07-01T04:34:38.945+0000] {taskinstance.py:2480} INFO - Exporting env vars: AIRFLOW_CTX_DAG_OWNER='***' AIRFLOW_CTX_DAG_ID='DAG_atualizacao_cadastral_revendas' AIRFLOW_CTX_TASK_ID='insert_database' AIRFLOW_CTX_EXECUTION_DATE='2025-06-30T04:30:00+00:00' AIRFLOW_CTX_TRY_NUMBER='1' AIRFLOW_CTX_DAG_RUN_ID='scheduled__2025-06-30T04:30:00+00:00'
[2025-07-01T04:34:39.004+0000] {base.py:83} INFO - Using connection ID 'dataset_comercial_database' for task execution.
[2025-07-01T04:34:40.399+0000] {taskinstance.py:2698} ERROR - Task failed with exception
Traceback (most recent call last):
  File "/opt/airflow/dags/DAG_atualizacao_cadastral_revendas/DatasetLoadedDataMining.py", line 77, in insert_database
    cursor.execute(query_update, (
psycopg2.errors.UndefinedColumn: column "longitude" of relation "registro_cadastral_revendas" does not exist
LINE 8:     longitude =  -49.4449688,
            ^


The above exception was the direct cause of the following exception:

Traceback (most recent call last):
  File "/home/airflow/.local/lib/python3.8/site-packages/airflow/models/taskinstance.py", line 433, in _execute_task
    result = execute_callable(context=context, **execute_callable_kwargs)
  File "/home/airflow/.local/lib/python3.8/site-packages/airflow/operators/python.py", line 199, in execute
    return_value = self.execute_callable()
  File "/home/airflow/.local/lib/python3.8/site-packages/airflow/operators/python.py", line 216, in execute_callable
    return self.python_callable(*self.op_args, **self.op_kwargs)
  File "/opt/airflow/dags/DAG_atualizacao_cadastral_revendas/DatasetLoadedDataMining.py", line 114, in insert_database
    raise RuntimeError("Erro ao inserir os dados no banco dataset") from erro
RuntimeError: Erro ao inserir os dados no banco dataset
[2025-07-01T04:34:40.435+0000] {taskinstance.py:1138} INFO - Marking task as FAILED. dag_id=DAG_atualizacao_cadastral_revendas, task_id=insert_database, execution_date=20250630T043000, start_date=20250701T043438, end_date=20250701T043440
[2025-07-01T04:34:40.554+0000] {standard_task_runner.py:107} ERROR - Failed to execute job 320 for task insert_database (Erro ao inserir os dados no banco dataset; 538675)
[2025-07-01T04:34:40.576+0000] {local_task_job_runner.py:234} INFO - Task exited with return code 1
[2025-07-01T04:34:40.611+0000] {taskinstance.py:3280} INFO - 0 downstream tasks scheduled from follow-on schedule check
