[2025-07-18T18:59:19.313+0000] {taskinstance.py:1956} INFO - Dependencies all met for dep_context=non-requeueable deps ti=<TaskInstance: DAG_analise_desempenho_revendas.inserir_banco_dados manual__2025-07-18T18:58:53.487289+00:00 [queued]>
[2025-07-18T18:59:19.333+0000] {taskinstance.py:1956} INFO - Dependencies all met for dep_context=requeueable deps ti=<TaskInstance: DAG_analise_desempenho_revendas.inserir_banco_dados manual__2025-07-18T18:58:53.487289+00:00 [queued]>
[2025-07-18T18:59:19.333+0000] {taskinstance.py:2170} INFO - Starting attempt 1 of 1
[2025-07-18T18:59:19.548+0000] {taskinstance.py:2191} INFO - Executing <Task(PythonOperator): inserir_banco_dados> on 2025-07-18 18:58:53.487289+00:00
[2025-07-18T18:59:19.560+0000] {standard_task_runner.py:60} INFO - Started process 1445360 to run task
[2025-07-18T18:59:19.570+0000] {standard_task_runner.py:87} INFO - Running: ['***', 'tasks', 'run', 'DAG_analise_desempenho_revendas', 'inserir_banco_dados', 'manual__2025-07-18T18:58:53.487289+00:00', '--job-id', '571', '--raw', '--subdir', 'DAGS_FOLDER/DagAnaliseDesempenhoRevendas.py', '--cfg-path', '/tmp/tmpxjrt49lo']
[2025-07-18T18:59:19.577+0000] {standard_task_runner.py:88} INFO - Job 571: Subtask inserir_banco_dados
[2025-07-18T18:59:20.020+0000] {task_command.py:423} INFO - Running <TaskInstance: DAG_analise_desempenho_revendas.inserir_banco_dados manual__2025-07-18T18:58:53.487289+00:00 [running]> on host 99f5714845f7
[2025-07-18T18:59:20.390+0000] {taskinstance.py:2480} INFO - Exporting env vars: AIRFLOW_CTX_DAG_OWNER='***' AIRFLOW_CTX_DAG_ID='DAG_analise_desempenho_revendas' AIRFLOW_CTX_TASK_ID='inserir_banco_dados' AIRFLOW_CTX_EXECUTION_DATE='2025-07-18T18:58:53.487289+00:00' AIRFLOW_CTX_TRY_NUMBER='1' AIRFLOW_CTX_DAG_RUN_ID='manual__2025-07-18T18:58:53.487289+00:00'
[2025-07-18T18:59:20.458+0000] {base.py:83} INFO - Using connection ID 'dataset_comercial_database' for task execution.
[2025-07-18T18:59:42.862+0000] {AnaliseDesempenhoRevendas.py:207} ERROR - Erro ao realizar a inserção dentro do banco de dados: integer out of range

[2025-07-18T18:59:42.863+0000] {taskinstance.py:2698} ERROR - Task failed with exception
Traceback (most recent call last):
  File "/home/airflow/.local/lib/python3.8/site-packages/airflow/models/taskinstance.py", line 433, in _execute_task
    result = execute_callable(context=context, **execute_callable_kwargs)
  File "/home/airflow/.local/lib/python3.8/site-packages/airflow/operators/python.py", line 199, in execute
    return_value = self.execute_callable()
  File "/home/airflow/.local/lib/python3.8/site-packages/airflow/operators/python.py", line 216, in execute_callable
    return self.python_callable(*self.op_args, **self.op_kwargs)
  File "/opt/airflow/dags/DAG_atualizacao_desempenho_revendas/AnaliseDesempenhoRevendas.py", line 183, in inserir_banco_dados
    cursor.execute(
psycopg2.errors.NumericValueOutOfRange: integer out of range

[2025-07-18T18:59:42.938+0000] {taskinstance.py:1138} INFO - Marking task as FAILED. dag_id=DAG_analise_desempenho_revendas, task_id=inserir_banco_dados, execution_date=20250718T185853, start_date=20250718T185919, end_date=20250718T185942
[2025-07-18T18:59:42.991+0000] {standard_task_runner.py:107} ERROR - Failed to execute job 571 for task inserir_banco_dados (integer out of range
; 1445360)
[2025-07-18T18:59:43.017+0000] {local_task_job_runner.py:234} INFO - Task exited with return code 1
[2025-07-18T18:59:43.047+0000] {taskinstance.py:3280} INFO - 0 downstream tasks scheduled from follow-on schedule check
