[2025-07-23T01:41:06.193+0000] {scheduler_job_runner.py:1586} WARNING - Marking task instance <TaskInstance: DAG_atualizacao_financeiro_intelidata.executar_query_gnio scheduled__2025-07-22T01:30:00+00:00 [queued]> stuck in queued as failed. If the task instance has available retries, it will be retried.
[2025-07-23T01:41:07.323+0000] {scheduler_job_runner.py:781} ERROR - Executor reports task instance <TaskInstance: DAG_atualizacao_financeiro_intelidata.executar_query_gnio scheduled__2025-07-22T01:30:00+00:00 [queued]> finished (failed) although the task says it's queued. (Info: None) Was the task killed externally?
