[2025-07-23T04:11:14.032+0000] {scheduler_job_runner.py:1586} WARNING - Marking task instance <TaskInstance: DAG_analise_desempenho_revendas.executar_query_gnio scheduled__2025-07-22T04:00:00+00:00 [queued]> stuck in queued as failed. If the task instance has available retries, it will be retried.
[2025-07-23T04:11:15.268+0000] {scheduler_job_runner.py:781} ERROR - Executor reports task instance <TaskInstance: DAG_analise_desempenho_revendas.executar_query_gnio scheduled__2025-07-22T04:00:00+00:00 [queued]> finished (failed) although the task says it's queued. (Info: None) Was the task killed externally?
