[2025-06-23T19:26:26.536+0000] {taskinstance.py:1956} INFO - Dependencies all met for dep_context=non-requeueable deps ti=<TaskInstance: relatorio_revendas_diario.enviar_para_elasticsearch manual__2025-06-23T19:26:12.788543+00:00 [queued]>
[2025-06-23T19:26:26.553+0000] {taskinstance.py:1956} INFO - Dependencies all met for dep_context=requeueable deps ti=<TaskInstance: relatorio_revendas_diario.enviar_para_elasticsearch manual__2025-06-23T19:26:12.788543+00:00 [queued]>
[2025-06-23T19:26:26.553+0000] {taskinstance.py:2170} INFO - Starting attempt 1 of 1
[2025-06-23T19:26:26.630+0000] {taskinstance.py:2191} INFO - Executing <Task(PythonOperator): enviar_para_elasticsearch> on 2025-06-23 19:26:12.788543+00:00
[2025-06-23T19:26:26.645+0000] {standard_task_runner.py:60} INFO - Started process 158712 to run task
[2025-06-23T19:26:26.651+0000] {standard_task_runner.py:87} INFO - Running: ['***', 'tasks', 'run', 'relatorio_revendas_diario', 'enviar_para_elasticsearch', 'manual__2025-06-23T19:26:12.788543+00:00', '--job-id', '130', '--raw', '--subdir', 'DAGS_FOLDER/DagEnviarRelatorioDesempenho.py', '--cfg-path', '/tmp/tmpbqignluk']
[2025-06-23T19:26:26.657+0000] {standard_task_runner.py:88} INFO - Job 130: Subtask enviar_para_elasticsearch
[2025-06-23T19:26:26.832+0000] {task_command.py:423} INFO - Running <TaskInstance: relatorio_revendas_diario.enviar_para_elasticsearch manual__2025-06-23T19:26:12.788543+00:00 [running]> on host 99f5714845f7
[2025-06-23T19:26:27.149+0000] {taskinstance.py:2480} INFO - Exporting env vars: AIRFLOW_CTX_DAG_OWNER='***' AIRFLOW_CTX_DAG_ID='relatorio_revendas_diario' AIRFLOW_CTX_TASK_ID='enviar_para_elasticsearch' AIRFLOW_CTX_EXECUTION_DATE='2025-06-23T19:26:12.788543+00:00' AIRFLOW_CTX_TRY_NUMBER='1' AIRFLOW_CTX_DAG_RUN_ID='manual__2025-06-23T19:26:12.788543+00:00'
[2025-06-23T19:26:27.211+0000] {_transport.py:358} INFO - HEAD http://127.0.0.1:9200/ [status:N/A duration:0.002s]
[2025-06-23T19:26:27.212+0000] {_node_pool.py:249} WARNING - Node <Urllib3HttpNode(http://127.0.0.1:9200)> has failed for 1 times in a row, putting on 1 second timeout
[2025-06-23T19:26:27.213+0000] {_transport.py:395} WARNING - Retrying request after failure (attempt 0 of 3)
Traceback (most recent call last):
  File "/home/airflow/.local/lib/python3.8/site-packages/elastic_transport/_transport.py", line 328, in perform_request
    meta, raw_data = node.perform_request(
  File "/home/airflow/.local/lib/python3.8/site-packages/elastic_transport/_node/_http_urllib3.py", line 202, in perform_request
    raise err from None
elastic_transport.ConnectionError: Connection error caused by: NewConnectionError(<urllib3.connection.HTTPConnection object at 0x7f6ff6d70250>: Failed to establish a new connection: [Errno 111] Connection refused)
[2025-06-23T19:26:27.580+0000] {_transport.py:358} INFO - HEAD http://127.0.0.1:9200/ [status:N/A duration:0.001s]
[2025-06-23T19:26:27.581+0000] {_node_pool.py:249} WARNING - Node <Urllib3HttpNode(http://127.0.0.1:9200)> has failed for 2 times in a row, putting on 2 second timeout
[2025-06-23T19:26:27.581+0000] {_transport.py:395} WARNING - Retrying request after failure (attempt 1 of 3)
Traceback (most recent call last):
  File "/home/airflow/.local/lib/python3.8/site-packages/elastic_transport/_transport.py", line 328, in perform_request
    meta, raw_data = node.perform_request(
  File "/home/airflow/.local/lib/python3.8/site-packages/elastic_transport/_node/_http_urllib3.py", line 202, in perform_request
    raise err from None
elastic_transport.ConnectionError: Connection error caused by: NewConnectionError(<urllib3.connection.HTTPConnection object at 0x7f6ff6d70400>: Failed to establish a new connection: [Errno 111] Connection refused)
[2025-06-23T19:26:27.584+0000] {_transport.py:358} INFO - HEAD http://127.0.0.1:9200/ [status:N/A duration:0.001s]
[2025-06-23T19:26:27.585+0000] {_node_pool.py:249} WARNING - Node <Urllib3HttpNode(http://127.0.0.1:9200)> has failed for 3 times in a row, putting on 4 second timeout
[2025-06-23T19:26:27.585+0000] {_transport.py:395} WARNING - Retrying request after failure (attempt 2 of 3)
Traceback (most recent call last):
  File "/home/airflow/.local/lib/python3.8/site-packages/elastic_transport/_transport.py", line 328, in perform_request
    meta, raw_data = node.perform_request(
  File "/home/airflow/.local/lib/python3.8/site-packages/elastic_transport/_node/_http_urllib3.py", line 202, in perform_request
    raise err from None
elastic_transport.ConnectionError: Connection error caused by: NewConnectionError(<urllib3.connection.HTTPConnection object at 0x7f6ff6d70640>: Failed to establish a new connection: [Errno 111] Connection refused)
[2025-06-23T19:26:27.587+0000] {_transport.py:358} INFO - HEAD http://127.0.0.1:9200/ [status:N/A duration:0.001s]
[2025-06-23T19:26:27.587+0000] {_node_pool.py:249} WARNING - Node <Urllib3HttpNode(http://127.0.0.1:9200)> has failed for 4 times in a row, putting on 8 second timeout
[2025-06-23T19:26:27.587+0000] {logging_mixin.py:188} INFO - Erro: n√£o conseguiu conectar no Elasticsearch!
[2025-06-23T19:26:27.588+0000] {python.py:201} INFO - Done. Returned value was: None
[2025-06-23T19:26:27.613+0000] {taskinstance.py:1138} INFO - Marking task as SUCCESS. dag_id=relatorio_revendas_diario, task_id=enviar_para_elasticsearch, execution_date=20250623T192612, start_date=20250623T192626, end_date=20250623T192627
[2025-06-23T19:26:27.760+0000] {local_task_job_runner.py:234} INFO - Task exited with return code 0
[2025-06-23T19:26:27.809+0000] {taskinstance.py:3280} INFO - 0 downstream tasks scheduled from follow-on schedule check
